<?xml version="1.0"?>
<robot name="my_robot" xmlns:xacro="http://www.ros.org/wiki/xacro">

    <!-- Add gazebo plugins file -->
    <xacro:include filename="$(find robot_description)/urdf/robot.gazebo.xacro"/>
    
    <!-- Add meshes folder -->
    <xacro:arg name="mesh_path" default="package://robot_description/meshes/"/>

    <!-- Materials -->
    <material name="green">
        <color rgba="0 0.6 0 1"/>
    </material>

    <material name="gray">
        <color rgba="0.7 0.7 0.7 1"/>
    </material>

    <material name="red">
        <color rgba="1 0 0 0.8"/>
    </material>

    <!-- Robot Dimensions -->
    <xacro:property name="base_length" value="0.6"/>
    <xacro:property name="base_width" value="0.4"/>
    <xacro:property name="base_height" value="0.2"/>
    <xacro:property name="base_mass" value="4.0" />

    <xacro:property name="wheel_radius" value="0.1"/>
    <xacro:property name="wheel_length" value="0.05"/>
    <xacro:property name="wheel_mass" value="0.2" />

    <xacro:property name="caster_wheel_mass" value="0.1" />

    <!-- Base Footprint -->
    <link name="base_footprint"/>

    <!-- Base Link -->
    <link name="base_link">
        <visual>
            <origin xyz="0 0 0" rpy="0 0 0"/>
            <geometry>
                <box size="${base_length} ${base_width} ${base_height}"/>
            </geometry>
            <material name="green"/>
        </visual>
        <collision>
            <origin xyz="0 0 0" rpy="0 0 0"/>
            <geometry>
                <box size="${base_length} ${base_width} ${base_height}"/>
            </geometry>
        </collision>
        <inertial>
            <mass value="${base_mass}"/>
            <origin xyz="0 0 0" rpy="0 0 0"/>
            <inertia
                ixx="${(1/12) * base_mass * (base_width*base_width + base_height*base_height)}"
                ixy="0.0"
                ixz="0.0"
                iyy="${(1/12) * base_mass * (base_length*base_length + base_height*base_height)}"
                iyz="0.0"
                izz="${(1/12) * base_mass * (base_length*base_length + base_width*base_width)}"/>
        </inertial>
    </link>

    <!-- Base Link is 15 cm above the ground -->
    <joint name="base_footprint_joint" type="fixed">
        <parent link="base_footprint"/>
        <child link="base_link"/>
        <origin xyz="0 0 0.15" rpy="0 0 0"/>
    </joint>

    <!-- macro for wheels -->
    <xacro:macro name="wheel" params="prefix x_reflect y_reflect">
        <link name="${prefix}_wheel_link">
            <visual>
                <origin xyz="0 0 0" rpy="${pi/2.0} 0 0"/>
                <geometry>
                    <cylinder radius="${wheel_radius}" length="${wheel_length}"/>
                </geometry>
                <material name="gray"/>
            </visual>
            <collision>
                <origin xyz="0 0 0" rpy="${pi/2} 0 0"/>
                <geometry>
                    <cylinder radius="${wheel_radius}" length="${wheel_length}"/>
                </geometry>
            </collision>
            <inertial>
                <mass value="${wheel_mass}"/>
                <origin xyz="0 0 0" rpy="${pi/2} 0 0"/>
                <inertia
                    ixx="${(1/12) * wheel_mass * (3*wheel_radius*wheel_radius + wheel_length*wheel_length)}"
                    ixy="0.0"
                    ixz="0.0"
                    iyy="${(1/12) * wheel_mass * (3*wheel_radius*wheel_radius + wheel_length*wheel_length)}"
                    iyz="0.0"
                    izz="${(1/2) * wheel_mass * (wheel_radius*wheel_radius)}"/>
            </inertial>
        </link>

        <joint name="${prefix}_wheel_joint" type="continuous">
            <parent link="base_link"/>
            <child link="${prefix}_wheel_link"/>
            <origin xyz="${x_reflect * (base_length/4.0)} ${y_reflect * ((base_width + wheel_length)/2.0)} -0.05" rpy="0 0 0"/>
            <axis xyz="0 1 0"/>
        </joint>
    </xacro:macro>

    <!-- Making two wheels for the robot -->
    <xacro:wheel prefix="right" x_reflect="-1" y_reflect="-1"/>
    <xacro:wheel prefix="left" x_reflect="-1" y_reflect="1"/>

    <!-- Caster Wheel -->
    <link name="caster_wheel">
        <visual>
            <origin xyz="0 0 0"/>
            <geometry>
                <sphere radius="${wheel_radius/2.0}"/>
            </geometry>
            <material name="red"/>
        </visual>
        <collision>
            <origin xyz="0 0 0"/>
            <geometry>
                <sphere radius="${wheel_radius/2.0}"/>
            </geometry>
        </collision>
        <inertial>
            <mass value="${caster_wheel_mass}"/>
            <origin xyz="0 0 0" rpy="0 0 0"/>
            <inertia
                ixx="${(2/5) * caster_wheel_mass * ((wheel_radius/2.0) * (wheel_radius/2.0))}"
                ixy="0.0"
                ixz="0.0"
                iyy="${(2/5) * caster_wheel_mass * ((wheel_radius/2.0) * (wheel_radius/2.0))}"
                iyz="0.0"
                izz="${(2/5) * caster_wheel_mass * ((wheel_radius/2.0) * (wheel_radius/2.0))}"/>
        </inertial>
    </link>

    <!-- Caster wheel joint -->
    <joint name="caster_wheel_joint" type="fixed">
        <parent link="base_link"/>
        <child link="caster_wheel"/>
        <origin xyz="${base_length/3.0} 0 -0.10" rpy="0 0 0"/>
    </joint>

    <!-- Lidar link -->
    <link name="lidar_link">
        <visual>
            <origin xyz="0 0 0" rpy="0 0 0"/>
            <geometry>
                <mesh filename="$(arg mesh_path)lidar.STL"/>
            </geometry>
            <material name="lidar_gray">
                <color rgba="0.6 0.6 0.6 1.0"/>
            </material>
        </visual>
        <collision>
            <origin xyz="0 0 0" rpy="0 0 0"/>
            <geometry>
                <mesh filename="$(arg mesh_path)lidar.STL"/>
            </geometry>
        </collision>
        <inertial>
            <mass value="0.2"/>
            <origin xyz="0 0 0" rpy="0 0 0"/>
            <inertia ixx="0.0001" ixy="0.0" ixz="0.0"
                    iyy="0.0001" iyz="0.0"
                    izz="0.0001"/>
        </inertial>
    </link>

    <!-- Lidar joint -->
    <joint name="lidar_joint" type="fixed">
        <parent link="base_link"/>
        <child link="lidar_link"/>
        <origin xyz="${base_length / 3.0} 0 ${base_height / 2.0 + 0.02}" rpy="0 0 0"/>
    </joint>

    <!-- Camera link -->
    <link name="camera_link">
        <visual>
            <origin xyz="0 0 0" rpy="0 0 0"/>
            <geometry>
                <mesh filename="$(arg mesh_path)zed.stl"/>
            </geometry>
            <material name="camera_black">
                <color rgba="0.5 0.5 0.5 1.0"/>
            </material>
        </visual>
        <collision>
            <origin xyz="0 0 0" rpy="0 0 0"/>
            <geometry>
                <mesh filename="$(arg mesh_path)zed.stl"/>
            </geometry>
        </collision>
        <inertial>
            <mass value="0.1"/>
            <origin xyz="0 0 0" rpy="0 0 0"/>
            <inertia ixx="0.00005" ixy="0.0" ixz="0.0"
                    iyy="0.00005" iyz="0.0"
                    izz="0.00005"/>
        </inertial>
    </link>

    <!-- Camera joint -->
    <joint name="camera_joint" type="fixed">
        <parent link="base_link"/>
        <child link="camera_link"/>
        <origin xyz="${base_length / 2.0} 0 ${base_height / 3.0}" rpy="0 0 0"/>
    </joint>

    <!-- Camera oprical -->
    <link name="camera_optical_link"/>

    <joint name="camera_optical_joint" type="fixed">
        <parent link="camera_link"/>
        <child link="camera_optical_link"/>
        <origin xyz="0 0 0" rpy="-1.5708 0 -1.5708"/>
    </joint>

</robot>